Traceback (most recent call last):
  File "/opt/hostedtoolcache/Python/3.11.13/x64/lib/python3.11/site-packages/jupyter_core/utils/__init__.py", line 154, in wrapped
    asyncio.get_running_loop()
RuntimeError: no running event loop

During handling of the above exception, another exception occurred:

Traceback (most recent call last):
  File "/opt/hostedtoolcache/Python/3.11.13/x64/lib/python3.11/site-packages/jupyter_cache/executors/utils.py", line 58, in single_nb_execution
    executenb(
  File "/opt/hostedtoolcache/Python/3.11.13/x64/lib/python3.11/site-packages/nbclient/client.py", line 1319, in execute
    return NotebookClient(nb=nb, resources=resources, km=km, **kwargs).execute()
           ^^^^^^^^^^^^^^^^^^^^^^^^^^^^^^^^^^^^^^^^^^^^^^^^^^^^^^^^^^^^^^^^^^^^^
  File "/opt/hostedtoolcache/Python/3.11.13/x64/lib/python3.11/site-packages/jupyter_core/utils/__init__.py", line 158, in wrapped
    return loop.run_until_complete(inner)
           ^^^^^^^^^^^^^^^^^^^^^^^^^^^^^^
  File "/opt/hostedtoolcache/Python/3.11.13/x64/lib/python3.11/asyncio/base_events.py", line 654, in run_until_complete
    return future.result()
           ^^^^^^^^^^^^^^^
  File "/opt/hostedtoolcache/Python/3.11.13/x64/lib/python3.11/site-packages/nbclient/client.py", line 709, in async_execute
    await self.async_execute_cell(
  File "/opt/hostedtoolcache/Python/3.11.13/x64/lib/python3.11/site-packages/nbclient/client.py", line 1062, in async_execute_cell
    await self._check_raise_for_error(cell, cell_index, exec_reply)
  File "/opt/hostedtoolcache/Python/3.11.13/x64/lib/python3.11/site-packages/nbclient/client.py", line 918, in _check_raise_for_error
    raise CellExecutionError.from_cell_and_msg(cell, exec_reply_content)
nbclient.exceptions.CellExecutionError: An error occurred while executing the following cell:
------------------
import os
workdir='/root/soft/DeePTB/examples/GaAs_io_sk/data'
os.chdir(f"{workdir}")
!tree -L 1 ./
------------------


[31m---------------------------------------------------------------------------[39m
[31mPermissionError[39m                           Traceback (most recent call last)
[36mCell[39m[36m [39m[32mIn[3][39m[32m, line 3[39m
[32m      1[39m [38;5;28;01mimport[39;00m[38;5;250m [39m[34;01mos[39;00m
[32m      2[39m workdir=[33m'[39m[33m/root/soft/DeePTB/examples/GaAs_io_sk/data[39m[33m'[39m
[32m----> [39m[32m3[39m [43mos[49m[43m.[49m[43mchdir[49m[43m([49m[33;43mf[39;49m[33;43m"[39;49m[38;5;132;43;01m{[39;49;00m[43mworkdir[49m[38;5;132;43;01m}[39;49;00m[33;43m"[39;49m[43m)[49m
[32m      4[39m get_ipython().system([33m'[39m[33mtree -L 1 ./[39m[33m'[39m)

[31mPermissionError[39m: [Errno 13] Permission denied: '/root/soft/DeePTB/examples/GaAs_io_sk/data'

